{"trial_id": "1", "hyperparameters": {"space": [{"class_name": "Int", "config": {"name": "filters_1", "default": null, "conditions": [], "min_value": 16, "max_value": 64, "step": 16, "sampling": "linear"}}, {"class_name": "Int", "config": {"name": "filters_2", "default": null, "conditions": [], "min_value": 32, "max_value": 128, "step": 32, "sampling": "linear"}}, {"class_name": "Int", "config": {"name": "filters_3", "default": null, "conditions": [], "min_value": 64, "max_value": 256, "step": 64, "sampling": "linear"}}, {"class_name": "Int", "config": {"name": "dense_units", "default": null, "conditions": [], "min_value": 64, "max_value": 256, "step": 64, "sampling": "linear"}}], "values": {"filters_1": 64, "filters_2": 96, "filters_3": 128, "dense_units": 256}}, "metrics": {"metrics": {}}, "score": null, "best_step": 0, "status": "FAILED", "message": "Traceback (most recent call last):\n  File \"/home/ec2-user/anaconda3/envs/python3/lib/python3.10/site-packages/keras_tuner/src/engine/base_tuner.py\", line 273, in _try_run_and_update_trial\n    self._run_and_update_trial(trial, *fit_args, **fit_kwargs)\n  File \"/home/ec2-user/anaconda3/envs/python3/lib/python3.10/site-packages/keras_tuner/src/engine/base_tuner.py\", line 238, in _run_and_update_trial\n    results = self.run_trial(trial, *fit_args, **fit_kwargs)\n  File \"/home/ec2-user/anaconda3/envs/python3/lib/python3.10/site-packages/keras_tuner/src/engine/tuner.py\", line 314, in run_trial\n    obj_value = self._build_and_fit_model(trial, *args, **copied_kwargs)\n  File \"/home/ec2-user/anaconda3/envs/python3/lib/python3.10/site-packages/keras_tuner/src/engine/tuner.py\", line 233, in _build_and_fit_model\n    results = self.hypermodel.fit(hp, model, *args, **kwargs)\n  File \"/home/ec2-user/anaconda3/envs/python3/lib/python3.10/site-packages/keras_tuner/src/engine/hypermodel.py\", line 149, in fit\n    return model.fit(*args, **kwargs)\n  File \"/home/ec2-user/anaconda3/envs/python3/lib/python3.10/site-packages/keras/src/utils/traceback_utils.py\", line 70, in error_handler\n    raise e.with_traceback(filtered_tb) from None\n  File \"/home/ec2-user/anaconda3/envs/python3/lib/python3.10/site-packages/tensorflow/python/eager/execute.py\", line 60, in quick_execute\n    tensors = pywrap_tfe.TFE_Py_Execute(ctx._handle, device_name, op_name,\ntensorflow.python.framework.errors_impl.NotFoundError: Graph execution error:\n\nDetected at node sequential/conv2d/Relu defined at (most recent call last):\n  File \"/home/ec2-user/anaconda3/envs/python3/lib/python3.10/runpy.py\", line 196, in _run_module_as_main\n\n  File \"/home/ec2-user/anaconda3/envs/python3/lib/python3.10/runpy.py\", line 86, in _run_code\n\n  File \"/home/ec2-user/anaconda3/envs/python3/lib/python3.10/site-packages/ipykernel_launcher.py\", line 17, in <module>\n\n  File \"/home/ec2-user/anaconda3/envs/python3/lib/python3.10/site-packages/traitlets/config/application.py\", line 1053, in launch_instance\n\n  File \"/home/ec2-user/anaconda3/envs/python3/lib/python3.10/site-packages/ipykernel/kernelapp.py\", line 737, in start\n\n  File \"/home/ec2-user/anaconda3/envs/python3/lib/python3.10/site-packages/tornado/platform/asyncio.py\", line 195, in start\n\n  File \"/home/ec2-user/anaconda3/envs/python3/lib/python3.10/asyncio/base_events.py\", line 603, in run_forever\n\n  File \"/home/ec2-user/anaconda3/envs/python3/lib/python3.10/asyncio/base_events.py\", line 1909, in _run_once\n\n  File \"/home/ec2-user/anaconda3/envs/python3/lib/python3.10/asyncio/events.py\", line 80, in _run\n\n  File \"/home/ec2-user/anaconda3/envs/python3/lib/python3.10/site-packages/ipykernel/kernelbase.py\", line 524, in dispatch_queue\n\n  File \"/home/ec2-user/anaconda3/envs/python3/lib/python3.10/site-packages/ipykernel/kernelbase.py\", line 513, in process_one\n\n  File \"/home/ec2-user/anaconda3/envs/python3/lib/python3.10/site-packages/ipykernel/kernelbase.py\", line 418, in dispatch_shell\n\n  File \"/home/ec2-user/anaconda3/envs/python3/lib/python3.10/site-packages/ipykernel/kernelbase.py\", line 758, in execute_request\n\n  File \"/home/ec2-user/anaconda3/envs/python3/lib/python3.10/site-packages/ipykernel/ipkernel.py\", line 426, in do_execute\n\n  File \"/home/ec2-user/anaconda3/envs/python3/lib/python3.10/site-packages/ipykernel/zmqshell.py\", line 549, in run_cell\n\n  File \"/home/ec2-user/anaconda3/envs/python3/lib/python3.10/site-packages/IPython/core/interactiveshell.py\", line 3024, in run_cell\n\n  File \"/home/ec2-user/anaconda3/envs/python3/lib/python3.10/site-packages/IPython/core/interactiveshell.py\", line 3079, in _run_cell\n\n  File \"/home/ec2-user/anaconda3/envs/python3/lib/python3.10/site-packages/IPython/core/async_helpers.py\", line 129, in _pseudo_sync_runner\n\n  File \"/home/ec2-user/anaconda3/envs/python3/lib/python3.10/site-packages/IPython/core/interactiveshell.py\", line 3284, in run_cell_async\n\n  File \"/home/ec2-user/anaconda3/envs/python3/lib/python3.10/site-packages/IPython/core/interactiveshell.py\", line 3466, in run_ast_nodes\n\n  File \"/home/ec2-user/anaconda3/envs/python3/lib/python3.10/site-packages/IPython/core/interactiveshell.py\", line 3526, in run_code\n\n  File \"/tmp/ipykernel_98880/3518733839.py\", line 100, in <module>\n\n  File \"/home/ec2-user/anaconda3/envs/python3/lib/python3.10/site-packages/keras_tuner/src/engine/base_tuner.py\", line 233, in search\n\n  File \"/home/ec2-user/anaconda3/envs/python3/lib/python3.10/site-packages/keras_tuner/src/engine/base_tuner.py\", line 273, in _try_run_and_update_trial\n\n  File \"/home/ec2-user/anaconda3/envs/python3/lib/python3.10/site-packages/keras_tuner/src/engine/base_tuner.py\", line 238, in _run_and_update_trial\n\n  File \"/home/ec2-user/anaconda3/envs/python3/lib/python3.10/site-packages/keras_tuner/src/engine/tuner.py\", line 314, in run_trial\n\n  File \"/home/ec2-user/anaconda3/envs/python3/lib/python3.10/site-packages/keras_tuner/src/engine/tuner.py\", line 233, in _build_and_fit_model\n\n  File \"/home/ec2-user/anaconda3/envs/python3/lib/python3.10/site-packages/keras_tuner/src/engine/hypermodel.py\", line 149, in fit\n\n  File \"/home/ec2-user/anaconda3/envs/python3/lib/python3.10/site-packages/keras/src/utils/traceback_utils.py\", line 65, in error_handler\n\n  File \"/home/ec2-user/anaconda3/envs/python3/lib/python3.10/site-packages/keras/src/engine/training.py\", line 1783, in fit\n\n  File \"/home/ec2-user/anaconda3/envs/python3/lib/python3.10/site-packages/keras/src/engine/training.py\", line 1377, in train_function\n\n  File \"/home/ec2-user/anaconda3/envs/python3/lib/python3.10/site-packages/keras/src/engine/training.py\", line 1360, in step_function\n\n  File \"/home/ec2-user/anaconda3/envs/python3/lib/python3.10/site-packages/keras/src/engine/training.py\", line 1349, in run_step\n\n  File \"/home/ec2-user/anaconda3/envs/python3/lib/python3.10/site-packages/keras/src/engine/training.py\", line 1126, in train_step\n\n  File \"/home/ec2-user/anaconda3/envs/python3/lib/python3.10/site-packages/keras/src/utils/traceback_utils.py\", line 65, in error_handler\n\n  File \"/home/ec2-user/anaconda3/envs/python3/lib/python3.10/site-packages/keras/src/engine/training.py\", line 589, in __call__\n\n  File \"/home/ec2-user/anaconda3/envs/python3/lib/python3.10/site-packages/keras/src/utils/traceback_utils.py\", line 65, in error_handler\n\n  File \"/home/ec2-user/anaconda3/envs/python3/lib/python3.10/site-packages/keras/src/engine/base_layer.py\", line 1149, in __call__\n\n  File \"/home/ec2-user/anaconda3/envs/python3/lib/python3.10/site-packages/keras/src/utils/traceback_utils.py\", line 96, in error_handler\n\n  File \"/home/ec2-user/anaconda3/envs/python3/lib/python3.10/site-packages/keras/src/engine/sequential.py\", line 398, in call\n\n  File \"/home/ec2-user/anaconda3/envs/python3/lib/python3.10/site-packages/keras/src/engine/functional.py\", line 515, in call\n\n  File \"/home/ec2-user/anaconda3/envs/python3/lib/python3.10/site-packages/keras/src/engine/functional.py\", line 672, in _run_internal_graph\n\n  File \"/home/ec2-user/anaconda3/envs/python3/lib/python3.10/site-packages/keras/src/utils/traceback_utils.py\", line 65, in error_handler\n\n  File \"/home/ec2-user/anaconda3/envs/python3/lib/python3.10/site-packages/keras/src/engine/base_layer.py\", line 1149, in __call__\n\n  File \"/home/ec2-user/anaconda3/envs/python3/lib/python3.10/site-packages/keras/src/utils/traceback_utils.py\", line 96, in error_handler\n\n  File \"/home/ec2-user/anaconda3/envs/python3/lib/python3.10/site-packages/keras/src/layers/convolutional/base_conv.py\", line 321, in call\n\n  File \"/home/ec2-user/anaconda3/envs/python3/lib/python3.10/site-packages/keras/src/activations.py\", line 306, in relu\n\n  File \"/home/ec2-user/anaconda3/envs/python3/lib/python3.10/site-packages/keras/src/backend.py\", line 5397, in relu\n\nNo algorithm worked!  Error messages:\n  Profiling failure on CUDNN engine eng11{}: RESOURCE_EXHAUSTED: Out of memory while trying to allocate 16777216 bytes.\n  Profiling failure on CUDNN engine eng0{}: RESOURCE_EXHAUSTED: Out of memory while trying to allocate 16777216 bytes.\n\t [[{{node sequential/conv2d/Relu}}]] [Op:__inference_train_function_3731]\n"}